Workbook

Sheet TD
A3: Suma de Neto | B3: Etiquetas de columna
A4: Etiquetas de fila | B4: ENERO | C4: FEBRERO | D4: MARZO | F4: VARIACIÓN | G4: VAR. %
A5: ALIANZA FIDUCIARIA S.A | D5: 1423500 | F5: =+D5-C5 -> 1423500 | G5: =+IFERROR(D5/C5-1,0) -> 0
A6: BANCO AGRARIO DE COLOMBIA | B6: 2190 | C6: 20604 | F6: =+D6-C6 -> -20604 | G6: =+IFERROR(D6/C6-1,0) -> -1
A7: BANCO AGRARIO DE COLOMBIA S.A | C7: 11424.49 | D7: 12052 | F7: =+D7-C7 -> 627.51 | G7: =+IFERROR(D7/C7-1,0) -> 0.054926741
A8: BANCO DE BOGOTA | B8: 4303049 | C8: 1675065 | D8: 1802342 | F8: =+D8-C8 -> 127277 | G8: =+IFERROR(D8/C8-1,0) -> 0.07598332
A9: BANCO POPULAR | B9: 2650 | C9: 0 | D9: 15900 | F9: =+D9-C9 -> 15900 | G9: =+IFERROR(D9/C9-1,0) -> 0
A10: BANCOLOMBIA | B10: 4739977 | C10: 4209166.1 | D10: 40781.32 | F10: =+D10-C10 -> -4168384.8 | G10: =+IFERROR(D10/C10-1,0) -> -0.99031131
A11: BANCOLOMBIA PANAMA | B11: 514829.43 | C11: 284369.99 | D11: 475395.51 | F11: =+D11-C11 -> 191025.52 | G11: =+IFERROR(D11/C11-1,0) -> 0.67174993
A12: BBVA COLOMBIA S.A. | B12: 43927682 | C12: 51359812 | D12: 1.0580054e+08 | F12: =+D12-C12 -> 54440725 | G12: =+IFERROR(D12/C12-1,0) -> 1.0599868
A13: COMISIONES FACTORING BBVA BAVARIA-GOLOSINAS TRULULU-SUPER DE ALIMENTOS | D13: 59241903 | F13: =+D13-C13 -> 59241903 | G13: =+IFERROR(D13/C13-1,0) -> 0
A14: DEVOLUCION DE DSF - GASTOS BANCARIOS MES DE ENERO 2025 | C14: -43927682 | F14: =+D14-C14 -> 43927682 | G14: =+IFERROR(D14/C14-1,0) -> -1
A15: DEVOLUCION DE DSF - GASTOS BANCARIOS MES DE FEBRERO 2025 (DSF1104 AL 1114) | D15: -51359812 | F15: =+D15-C15 -> -51359812 | G15: =+IFERROR(D15/C15-1,0) -> 0
A16: FACTORING BBVA-29557-584-589-599-600-612-634-650 COMISION | D16: 12271970 | F16: =+D16-C16 -> 12271970 | G16: =+IFERROR(D16/C16-1,0) -> 0
A17: FACTORING BBVA FAN-29038 REGISTRO COMISION | C17: 1162707.3 | F17: =+D17-C17 -> -1162707.3 | G17: =+IFERROR(D17/C17-1,0) -> -1
A18: FACTORING BBVA FAN-29239 COMISIONES | C18: 1792877.1 | F18: =+D18-C18 -> -1792877.1 | G18: =+IFERROR(D18/C18-1,0) -> -1
A19: FACTORING BBVA FAN-29561 COMISION | D19: 1809003 | F19: =+D19-C19 -> 1809003 | G19: =+IFERROR(D19/C19-1,0) -> 0
A20: FACTORING BBVA FAN-29562-574-592-607-617-621-623-635-644-663-676 COMISIONES | D20: 14754923 | F20: =+D20-C20 -> 14754923 | G20: =+IFERROR(D20/C20-1,0) -> 0
A21: FACTORING BBVA-COMISIONES FAN-29218-251-256-288-309-324 | C21: 9251104.8 | F21: =+D21-C21 -> -9251104.8 | G21: =+IFERROR(D21/C21-1,0) -> -1
A22: GASTOS BANCARIOS CORRESPONDIENTES AL MES DE ENERO 2025 | C22: 43927682 | F22: =+D22-C22 -> -43927682 | G22: =+IFERROR(D22/C22-1,0) -> -1
A23: GASTOS BANCARIOS CORRESPONDIENTES AL MES DE FEBRERO 2025 | D23: 51359812 | F23: =+D23-C23 -> 51359812 | G23: =+IFERROR(D23/C23-1,0) -> 0
A24: RECLASIFICACION 529505 A 530515 COMISIONES BBVA - KLYM FEB 2025 | C24: 37562146 | F24: =+D24-C24 -> -37562146 | G24: =+IFERROR(D24/C24-1,0) -> -1
A25: RECLASIFICACION COMISIONES FACTORING BBVA NIC-36470 | D25: 16653282 | F25: =+D25-C25 -> 16653282 | G25: =+IFERROR(D25/C25-1,0) -> 0
A26: reclasificacion de cuentas en comision Factoring con Bavaria y Trululu | B26: 43927682 | F26: =+D26-C26 -> 0 | G26: =+IFERROR(D26/C26-1,0) -> 0
A27: RECLASIFICACION FAN-27800 A FAN - 27746 | C27: -639375 | F27: =+D27-C27 -> 639375 | G27: =+IFERROR(D27/C27-1,0) -> -1
A28: RECLASIFICION COMISIONES TRULULU FEB 2025 5295 A 5305 | C28: 2230352.2 | F28: =+D28-C28 -> -2230352.2 | G28: =+IFERROR(D28/C28-1,0) -> -1
A29: REGISTRO COMISION FACTORING BBVA | D29: 1069455.6 | F29: =+D29-C29 -> 1069455.6 | G29: =+IFERROR(D29/C29-1,0) -> 0
A30: COOPERATIVA COLANTA | D30: 1755101 | F30: =+D30-C30 -> 1755101 | G30: =+IFERROR(D30/C30-1,0) -> 0
A31: FACTORIN KLYM FAN-29555-29567-29582-29594 | D31: 1755101 | F31: =+D31-C31 -> 1755101 | G31: =+IFERROR(D31/C31-1,0) -> 0
A32: CORREAGRO S.A. | C32: 23022002 | D32: 19968668 | F32: =+D32-C32 -> -3053334 | G32: =+IFERROR(D32/C32-1,0) -> -0.13262678
A33: DAVIVIENDA | B33: 9801719 | C33: 8162148 | D33: 8069844 | F33: =+D33-C33 -> -92304 | G33: =+IFERROR(D33/C33-1,0) -> -0.011308788
A34: FIDUCIARIA DAVIVIENDA S.A | B34: 7426250 | C34: 3558750 | D34: 3558750.5 | F34: =+D34-C34 -> 0.5 | G34: =+IFERROR(D34/C34-1,0) -> 1.4049877e-07
A35: FIDUCIARIA POPULAR S.A. | B35: 3558750 | C35: 3558750 | D35: 4270500 | F35: =+D35-C35 -> 711750 | G35: =+IFERROR(D35/C35-1,0) -> 0.2
A36: ITAU CORPBANCA COLOMBIA SA | C36: 239997.6 | D36: 239997.6 | F36: =+D36-C36 -> 0 | G36: =+IFERROR(D36/C36-1,0) -> 0
A37: KLYM S.A.S | C37: 3496088 | F37: =+D37-C37 -> -3496088 | G37: =+IFERROR(D37/C37-1,0) -> -1
A38: SERVICIOS FINANCIEROS S.A. SERFINANZA CIA DE FINANCIAMIENTO | D38: 846982.5 | F38: =+D38-C38 -> 846982.5 | G38: =+IFERROR(D38/C38-1,0) -> 0
A39: Total general | B39: 74277097 | C39: 99598177 | D39: 1.4828035e+08
G40: =+GETPIVOTDATA("Neto",$A$3,"Mes",2)*G38 -> 0

Sheet TD 
A3: Suma de Neto | C3: Etiquetas de columna
A4: Etiquetas de fila | B4: Desc. auxiliar | C4: ENERO | D4: FEBRERO | E4: MARZO | F4: ABRIL | G4: MAYO | H4: 6 | I4: 7 | J4: 8 | K4: 9 | L4: 10
A5: 5502 - COMISIONES | C5: 74277097 | D5: 99598177 | E5: 1.1070745e+08 | F5: 1.1449795e+08 | G5: 1.2696958e+08 | H5: 99264624 | I5: 94136943 | J5: 55963595 | K5: 89318408 | L5: 1.7719002e+08
A6: 53051501 | B6: COMISIONES BANCARIAS | C6: 30349414 | D6: 21720275 | E6: 24705631 | F6: 20774654 | G6: 23685578 | H6: 19799540 | I6: 15160773 | J6: 11872594 | K6: 13893297 | L6: 10285606
B7: COMISIONES EN BOLSA | D7: 23022002 | E7: 19968668 | F7: -626070 | G7: 39499385 | H7: 15518647 | I7: 20002326 | J7: 23967947 | K7: 23705 | L7: 49513082
A8: 53051502 | B8: COMISIONES POR FACTORING | C8: 43927682 | D8: 54855900 | E8: 66033154 | F8: 94349366 | G8: 63784616 | H8: 63946437 | I8: 58973843 | J8: 20123054 | K8: 75401405 | L8: 1.1739133e+08
A9: Total general | C9: 74277097 | D9: 99598177 | E9: 1.1070745e+08 | F9: 1.1449795e+08 | G9: 1.2696958e+08 | H9: 99264624 | I9: 94136943 | J9: 55963595 | K9: 89318408 | L9: 1.7719002e+08

Sheet COMISIONES ENERO-MARZO 2025
A1: C.Costo | B1: Desc. C.Costo | C1: CUENTA | D1: Auxiliar | E1: Desc. auxiliar | F1: Neto | G1: Docto. | H1: Fecha | I1: Notas | J1: Notas docto | K1: Razón social tercero movto. | L1: SECCION | M1: Prefijo tipo docto | N1: SUB SUBCUENTA | O1: Mes
C2: 5502 - COMISIONES | D2: 53051501 | E2: BANCOS COMISIONES | F2: 38140 | G2: DSF-00001059 | H2: 45686 | I2: GASTOS BANCARIOS 27 AL 31 DICIEMBRE 2024 -BGTA CALI | J2: GASTOS BANCARIOS 27 AL 31 DICIEMBRE 2024 | K2: BANCO DE BOGOTA | M2: DSF | O2: =+MONTH(H2) -> 1
C3: 5502 - COMISIONES | D3: 53051501 | E3: BANCOS COMISIONES | F3: 78520 | G3: DSF-00001059 | H3: 45686 | I3: GASTOS BANCARIOS 27 AL 31 DICIEMBRE 2024 -BGTA TULUA | J3: GASTOS BANCARIOS 27 AL 31 DICIEMBRE 2024 | K3: BANCO DE BOGOTA | M3: DSF | O3: =+MONTH(H3) -> 1
C4: 5502 - COMISIONES | D4: 53051501 | E4: BANCOS COMISIONES | F4: 2500 | G4: DSF-00001060 | H4: 45686 | I4: GASTOS BANCARIOS 27 AL 31 DICIEMBRE 2024 -POPULAR 2276 | J4: GASTOS BANCARIOS 27 AL 31 DICIEMBRE 2024 -POPULAR 2276 | K4: BANCO POPULAR | M4: DSF | O4: =+MONTH(H4) -> 1
C5: 5502 - COMISIONES | D5: 53051501 | E5: BANCOS COMISIONES | F5: 125906.09 | G5: DSF-00001061 | H5: 45686 | I5: GASTOS BANCARIOS 27 AL 31 DICIEMBRE 2024 -BANCOLOMBIA 801 | J5: GASTOS BANCARIOS 27 AL 31 DICIEMBRE 2024 -BANCOLOMBIA | K5: BANCOLOMBIA | M5: DSF | O5: =+MONTH(H5) -> 1
C6: 5502 - COMISIONES | D6: 53051501 | E6: BANCOS COMISIONES | F6: 16560 | G6: DSF-00001061 | H6: 45686 | I6: GASTOS BANCARIOS 27 AL 31 DICIEMBRE 2024 -BANCOLOMBIA ESPECIAL | J6: GASTOS BANCARIOS 27 AL 31 DICIEMBRE 2024 -BANCOLOMBIA | K6: BANCOLOMBIA | M6: DSF | O6: =+MONTH(H6) -> 1
C7: 5502 - COMISIONES | D7: 53051501 | E7: BANCOS COMISIONES | F7: 4303049 | G7: DSF-00001074 | H7: 45707 | I7: GASTOS BANCARIOS CORRESPONDIENTES AL MES DE ENERO 2025 | J7: GASTOS BANCARIOS CORRESPONDIENTES AL MES DE ENERO 2025 | K7: BANCO DE BOGOTA | M7: DSF | O7: =+MONTH(H7) -> 2
C8: 5502 - COMISIONES | D8: 53051501 | E8: BANCOS COMISIONES | F8: 4739977 | G8: DSF-00001076 | H8: 45707 | I8: GASTOS BANCARIOS CORRESPONDIENTES AL MES DE ENERO 2025 | J8: GASTOS BANCARIOS CORRESPONDIENTES AL MES DE ENERO 2025 | K8: BANCOLOMBIA | M8: DSF | O8: =+MONTH(H8) -> 2
C9: 5502 - COMISIONES | D9: 53051501 | E9: BANCOS COMISIONES | F9: 9801719 | G9: DSF-00001077 | H9: 45707 | I9: GASTOS BANCARIOS CORRESPONDIENTES AL MES DE ENERO 2025 | J9: GASTOS BANCARIOS CORRESPONDIENTES AL MES DE ENERO 2025 | K9: DAVIVIENDA | M9: DSF | O9: =+MONTH(H9) -> 2
C10: 5502 - COMISIONES | D10: 53051501 | E10: BANCOS COMISIONES | F10: 2190 | G10: DSF-00001078 | H10: 45707 | I10: GASTOS BANCARIOS CORRESPONDIENTES AL MES DE ENERO 2025 | J10: GASTOS BANCARIOS CORRESPONDIENTES AL MES DE ENERO 2025 | K10: BANCO AGRARIO DE COLOMBIA S.A | M10: DSF | O10: =+MONTH(H10) -> 2
C11: 5502 - COMISIONES | D11: 53051501 | E11: BANCOS COMISIONES | F11: 2650 | G11: DSF-00001079 | H11: 45707 | I11: GASTOS BANCARIOS CORRESPONDIENTES AL MES DE ENERO 2025 | J11: GASTOS BANCARIOS CORRESPONDIENTES AL MES DE ENERO 2025 | K11: BANCO POPULAR | M11: DSF | O11: =+MONTH(H11) -> 2
C12: 5502 - COMISIONES | D12: 53051501 | E12: BANCOS COMISIONES | F12: 43927682 | G12: DSF-00001081 | H12: 45707 | I12: GASTOS BANCARIOS CORRESPONDIENTES AL MES DE ENERO 2025 | J12: GASTOS BANCARIOS CORRESPONDIENTES AL MES DE ENERO 2025 | K12: BBVA COLOMBIA S.A. | M12: DSF | O12: =+MONTH(H12) -> 2
C13: 5502 - COMISIONES | D13: 53051501 | E13: BANCOS COMISIONES | F13: 3558750 | G13: DSF-00001082 | H13: 45707 | I13: GASTOS BANCARIOS CORRESPONDIENTES AL MES DE ENERO 2025 | J13: GASTOS BANCARIOS CORRESPONDIENTES AL MES DE ENERO 2025 | K13: FIDUCIARIA POPULAR S.A. | M13: DSF | O13: =+MONTH(H13) -> 2
... C23: 5502 - COMISIONES | D23: 53051501 | E23: BANCOS COMISIONES | F23: 284369.99 | G23: DSF-00001114 | H23: 45737 | I23: GASTOS BANCARIOS CORRESPONDIENTES AL MES DE FEBRERO 2025 | J23: GASTOS BANCARIOS CORRESPONDIENTES AL MES DE FEBRERO 2025 | K23: BANCOLOMBIA PANAMA | M23: DSF | O23: =+MONTH(H23) -> 3
C24: 5502 - COMISIONES | D24: 53051501 | E24: BANCOS COMISIONES | F24: 3558750 | G24: FAC-00045087 | H24: 45688 | I24: FAC132801 - COMISION FIDUCIARIA MES DE ENERO 2025- COMISION FIJA 2.5 SMMLV | J24: FAC132801 - COMISION FIDUCIARIA MES DE ENERO 2025- COMISION FIJA 2.5 SMMLV | K24: FIDUCIARIA POPULAR S.A. | O24: =+MONTH(H24) -> 1
C25: 5502 - COMISIONES | D25: 53051501 | E25: BANCOS COMISIONES | F25: 3558750 | G25: FAC-00045088 | H25: 45688 | I25: SOC81109 - COMISION POR ADMINISTRACION MES DE ENERO 2025 - EA | J25: SOC81109 - COMISION POR ADMINISTRACION MES DE ENERO 2025 - EA | K25: FIDUCIARIA DAVIVIENDA S.A | O25: =+MONTH(H25) -> 1
C26: 5502 - COMISIONES | D26: 53051501 | E26: BANCOS COMISIONES | F26: 3558750 | G26: FAC-00045545 | H26: 45716 | I26: SOC82093 - D1- COMISION POR ADMINISTRACION, PERIODO DE FACTRUACION: FEBRERO 2025 | J26: SOC82093 - D1- COMISION POR ADMINISTRACION, PERIODO DE FACTRUACION: FEBRERO 2025 | K26: FIDUCIARIA DAVIVIENDA S.A | O26: =+MONTH(H26) -> 2
C27: 5502 - COMISIONES | D27: 53051501 | E27: BANCOS COMISIONES | F27: 3558750 | G27: FAC-00045546 | H27: 45716 | I27: FAC133255 - COMISION FIDUCIARIA MES DE FEBRERO 2025- COMISION FIJA 2.5 SMMLV | J27: FAC133255 - COMISION FIDUCIARIA MES DE FEBRERO 2025- COMISION FIJA 2.5 SMMLV | K27: FIDUCIARIA POPULAR S.A. | O27: =+MONTH(H27) -> 2
C28: 5502 - COMISIONES | D28: 53051501 | E28: BANCOS COMISIONES | F28: 711750 | G28: FAC-00045697 | H28: 45733 | I28: FAC133431 - COMISION FIDUCIARIA POR EXPEDICION DE CERTIFICADO DE GARANTIA 20 | J28: FAC133431 - COMISION FIDUCIARIA POR EXPEDICION DE CERTIFICADO DE GARANTIA 20 | K28: FIDUCIARIA POPULAR S.A. | O28: =+MONTH(H28) -> 3
C29: 5502 - COMISIONES | D29: 53051501 | E29: BANCOS COMISIONES | F29: 3558750 | G29: FAC-00045698 | H29: 45733 | I29: FAC133535 - COMISION FIDUCIARIA MES DE MARZO 2025 - COMISION FIJA 2.5 SMMLV | J29: FAC133535 - COMISION FIDUCIARIA MES DE MARZO 2025 - COMISION FIJA 2.5 SMMLV | K29: FIDUCIARIA POPULAR S.A. | O29: =+MONTH(H29) -> 3
C30: 5502 - COMISIONES | D30: 53051501 | E30: BANCOS COMISIONES | F30: 3558750 | G30: FAC-00045701 | H30: 45733 | I30: SOC83617 - COMISION POR ADMINISTRACION - PERIODO DE FACTURACION MARZO 2025 | J30: SOC83617 - COMISION POR ADMINISTRACION - PERIODO DE FACTURACION MARZO 2025 | K30: FIDUCIARIA DAVIVIENDA S.A | O30: =+MONTH(H30) -> 3
C31: 5502 - COMISIONES | D31: 53051501 | E31: BANCOS COMISIONES | F31: 1423500 | G31: FAC-00045724 | H31: 45736 | I31: FAC992663 - COMISION FIJA DE ADMINISTRACION CORRESPONDIENTE AL MES DE MARZO 2025 | J31: FAC992663 - COMISION FIJA DE ADMINISTRACION CORRESPONDIENTE AL MES DE MARZO 2025 | K31: ALIANZA FIDUCIARIA S.A | O31: =+MONTH(H31) -> 3
C32: 5502 - COMISIONES | D32: 53051501 | E32: BANCOS COMISIONES | F32: 2190 | G32: NIB-00005736 | H32: 45664 | I32: PAGO DE DEPOSITOS JUDICIALES - COMPROBANTE DE PAGO: 1491465 - ARCHIVO: 30030 - INGENIO CARMELITA - ARCHIVO: GD20250107018919001961 | J32: PAGO DE DEPOSITOS JUDICIALES - COMPROBANTE DE PAGO: 1491465 - ARCHIVO: 30030 - INGENIO CARMELITA - ARCHIVO: GD20250107018919001961 | K32: BANCO AGRARIO DE COLOMBIA | O32: =+MONTH(H32) -> 1
C33: 5502 - COMISIONES | D33: 53051501 | E33: BANCOS COMISIONES | F33: 9600.49 | G33: NIB-00005875 | H33: 45688 | I33: COSTO DE TRANSACCION -PAGO DE FACTURAS A NOMBRE DE INGENIERIA Y EQUIPOS PARA LA INGENIERIA | J33: PAGO DE FACTURAS A NOMBRE DE INGENIERIA Y EQUIPOS PARA LA INGENIERIA | K33: BANCOLOMBIA | O33: =+MONTH(H33) -> 1
C34: 5502 - COMISIONES | D34: 53051501 | E34: BANCOS COMISIONES | F34: 1824 | G34: NIB-00005875 | H34: 45688 | I34: IVA DE TRANSACCION -PAGO DE FACTURAS A NOMBRE DE INGENIERIA Y EQUIPOS PARA LA INGENIERIA | J34: PAGO DE FACTURAS A NOMBRE DE INGENIERIA Y EQUIPOS PARA LA INGENIERIA | K34: BANCOLOMBIA | O34: =+MONTH(H34) -> 1
C35: 5502 - COMISIONES | D35: 53051501 | E35: BANCOS COMISIONES | F35: 3867500 | G35: NIB-00005899 | H35: 45688 | I35: COMISION FIJA MES DE ENERO 2025 | J35: GASTOS BANCARIOS MES DE ENERO 2025 FIDEICOMISO 42112858 - RENTA LIQUIDAN GASTOS BANCARIOS MES DE ENERO 2025 FIDEICOMISO 42112858 - RENTA LIQUIDA | K35: FIDUCIARIA DAVIVIENDA S.A | O35: =+MONTH(H35) -> 1
... C127: 5502 - COMISIONES | D127: 53051501 | E127: BANCOS COMISIONES | F127: 4782185 | G127: NIP-00016935 | H127: 45747 | I127: CLFV21376 - SERV REGISTRADO BMC 8600071250 | J127: CLFV21376 - SERV REGISTRADO BMC 8600071250 | K127: CORREAGRO S.A. | O127: =+MONTH(H127) -> 3
A128: Gran total | F128: 3.2215562e+08 | O128: =+MONTH(H128) -> 1

Sheet COMISIONES ENERO-MARZO 2025 (2)
A1: C.Costo | B1: Desc. C.Costo | C1: CUENTA | D1: Auxiliar | E1: Desc. auxiliar | F1: Neto | G1: Docto. | H1: Fecha | I1: Notas | J1: Notas docto | K1: Razón social tercero movto. | L1: SECCION | M1: Prefijo tipo docto | N1: SUB SUBCUENTA | O1: Mes | P1: Nombre Mes | X1: 1 | Y1: Enero
C2: 5502 - COMISIONES | D2: 53051501 | E2: COMISIONES BANCARIAS | F2: 2190 | G2: NIB-00005736 | H2: 45664 | I2: PAGO DE DEPOSITOS JUDICIALES - COMPROBANTE DE PAGO: 1491465 - ARCHIVO: 30030 - INGENIO CARMELITA - ARCHIVO: GD20250107018919001961 | J2: PAGO DE DEPOSITOS JUDICIALES - COMPROBANTE DE PAGO: 1491465 - ARCHIVO: 30030 - INGENIO CARMELITA - ARCHIVO: GD20250107018919001961 | K2: BANCO AGRARIO DE COLOMBIA S.A | M2: DSF | O2: =+MONTH(H2) -> 1 | P2: =+VLOOKUP(O2,$X:$Y,2,0) -> Enero | X2: 2 | Y2: Febrero
C3: 5502 - COMISIONES | D3: 53051501 | E3: COMISIONES BANCARIAS | F3: 3529 | G3: NIP-00016497 | H3: 45665 | I3: CONTABILIZACIÓN IVA COMISON 4*1000 | J3: CONTABILIZACIÓN IVA COMISON 4*1000 | K3: BANCOLOMBIA | M3: DSF | O3: =+MONTH(H3) -> 1 | P3: =+VLOOKUP(O3,X:Y,2,0) -> Enero | X3: 3 | Y3: Marzo
C4: 5502 - COMISIONES | D4: 53051501 | E4: COMISIONES BANCARIAS | F4: 7058 | G4: NIP-00016498 | H4: 45665 | I4: CONTABILIZACIÓN IVA COMISON 4*1000 | J4: CONTABILIZACIÓN IVA COMISON 4*1000 | K4: BANCOLOMBIA | M4: DSF | O4: =+MONTH(H4) -> 1 | P4: =+VLOOKUP(O4,X:Y,2,0) -> Enero | X4: 4 | Y4: Abril
C5: 5502 - COMISIONES | D5: 53051501 | E5: COMISIONES BANCARIAS | F5: 3529 | G5: NIP-00016519 | H5: 45671 | I5: CONTABILIZACIÓN IVA COMISION 4*1000 | J5: CONTABILIZACIÓN IVA COMISION 4*1000 | K5: BANCOLOMBIA | M5: DSF | O5: =+MONTH(H5) -> 1 | P5: =+VLOOKUP(O5,X:Y,2,0) -> Enero | X5: 5 | Y5: Mayo
C6: 5502 - COMISIONES | D6: 53051501 | E6: COMISIONES BANCARIAS | F6: 2650 | G6: NIB-00005915 | H6: 45674 | I6: GASTOS BANCARIOS POPULAR 2276 MES DE ENERO 2025 | J6: GASTOS BANCARIOS POPULAR 2276 MES DE ENERO 2025 | K6: BANCO POPULAR | M6: DSF | O6: =+MONTH(H6) -> 1 | P6: =+VLOOKUP(O6,X:Y,2,0) -> Enero | X6: 6 | Y6: Junio
C7: 5502 - COMISIONES | D7: 53051501 | E7: COMISIONES BANCARIAS | F7: 3529 | G7: NIP-00016556 | H7: 45678 | I7: CONTAN¿BILIZACIÓN IVA 4*1000 COMISION | J7: CONTAN¿BILIZACIÓN IVA 4*1000 COMISION | K7: BANCOLOMBIA | M7: DSF | O7: =+MONTH(H7) -> 1 | P7: =+VLOOKUP(O7,X:Y,2,0) -> Enero | X7: 7 | Y7: Julio
C8: 5502 - COMISIONES | D8: 53051501 | E8: COMISIONES BANCARIAS | F8: 3529 | G8: NIP-00016562 | H8: 45679 | I8: contabilización iva comision 4*1000 | J8: contabilización iva comision 4*1000 | K8: BANCOLOMBIA | M8: DSF | O8: =+MONTH(H8) -> 1 | P8: =+VLOOKUP(O8,X:Y,2,0) -> Enero | X8: 8 | Y8: Agosto
C9: 5502 - COMISIONES | D9: 53051501 | E9: COMISIONES BANCARIAS | F9: 3529 | G9: NIP-00016588 | H9: 45684 | I9: CONTABILIZACIÓN IVA COMISION 4*1000 | J9: CONTABILIZACIÓN IVA COMISION 4*1000 | K9: BANCOLOMBIA | M9: DSF | O9: =+MONTH(H9) -> 1 | P9: =+VLOOKUP(O9,X:Y,2,0) -> Enero | X9: 9 | Y9: Septiembre
C10: 5502 - COMISIONES | D10: 53051501 | E10: COMISIONES BANCARIAS | F10: 38140 | G10: DSF-00001059 | H10: 45686 | I10: GASTOS BANCARIOS 27 AL 31 DICIEMBRE 2024 -BGTA CALI | J10: GASTOS BANCARIOS 27 AL 31 DICIEMBRE 2024 | K10: BANCO DE BOGOTA | M10: DSF | O10: =+MONTH(H10) -> 1 | P10: =+VLOOKUP(O10,X:Y,2,0) -> Enero | X10: 10 | Y10: Octubre
C11: 5502 - COMISIONES | D11: 53051501 | E11: COMISIONES BANCARIAS | F11: 78520 | G11: DSF-00001059 | H11: 45686 | I11: GASTOS BANCARIOS 27 AL 31 DICIEMBRE 2024 -BGTA TULUA | J11: GASTOS BANCARIOS 27 AL 31 DICIEMBRE 2024 | K11: BANCO DE BOGOTA | M11: DSF | O11: =+MONTH(H11) -> 1 | P11: =+VLOOKUP(O11,X:Y,2,0) -> Enero | X11: 11 | Y11: Noviembre
C12: 5502 - COMISIONES | D12: 53051501 | E12: COMISIONES BANCARIAS | F12: 2500 | G12: DSF-00001060 | H12: 45686 | I12: GASTOS BANCARIOS 27 AL 31 DICIEMBRE 2024 -POPULAR 2276 | J12: GASTOS BANCARIOS 27 AL 31 DICIEMBRE 2024 -POPULAR 2276 | K12: BANCO POPULAR | M12: DSF | O12: =+MONTH(H12) -> 1 | P12: =+VLOOKUP(O12,X:Y,2,0) -> Enero | X12: 12 | Y12: Diciembre
C13: 5502 - COMISIONES | D13: 53051501 | E13: COMISIONES BANCARIAS | F13: 125906.09 | G13: DSF-00001061 | H13: 45686 | I13: GASTOS BANCARIOS 27 AL 31 DICIEMBRE 2024 -BANCOLOMBIA 801 | J13: GASTOS BANCARIOS 27 AL 31 DICIEMBRE 2024 -BANCOLOMBIA | K13: BANCOLOMBIA | M13: DSF | O13: =+MONTH(H13) -> 1 | P13: =+VLOOKUP(O13,X:Y,2,0) -> Enero
C14: 5502 - COMISIONES | D14: 53051501 | E14: COMISIONES BANCARIAS | F14: 16560 | G14: DSF-00001061 | H14: 45686 | I14: GASTOS BANCARIOS 27 AL 31 DICIEMBRE 2024 -BANCOLOMBIA ESPECIAL | J14: GASTOS BANCARIOS 27 AL 31 DICIEMBRE 2024 -BANCOLOMBIA | K14: BANCOLOMBIA | M14: DSF | O14: =+MONTH(H14) -> 1 | P14: =+VLOOKUP(O14,X:Y,2,0) -> Enero
C15: 5502 - COMISIONES | D15: 53051501 | E15: COMISIONES BANCARIAS | F15: -125906.09 | G15: NIC-00035976 | H15: 45686 | I15: GASTOS BANCARIOS 27 AL 31 DICIEMBRE 2024 -BANCOLOMBIA 801 | J15: DEVOLUCION DE DSF 1059-1060-1061 - GASTOS BANCARIOS 27 AL 31 DIC 2024 | K15: BANCOLOMBIA | M15: DSF | O15: =+MONTH(H15) -> 1 | P15: =+VLOOKUP(O15,X:Y,2,0) -> Enero
C16: 5502 - COMISIONES | D16: 53051501 | E16: COMISIONES BANCARIAS | F16: -16560 | G16: NIC-00035976 | H16: 45686 | I16: GASTOS BANCARIOS 27 AL 31 DICIEMBRE 2024 -BANCOLOMBIA ESPECIAL | J16: DEVOLUCION DE DSF 1059-1060-1061 - GASTOS BANCARIOS 27 AL 31 DIC 2024 | K16: BANCOLOMBIA | M16: DSF | O16: =+MONTH(H16) -> 1 | P16: =+VLOOKUP(O16,X:Y,2,0) -> Enero
C17: 5502 - COMISIONES | D17: 53051501 | E17: COMISIONES BANCARIAS | F17: -38140 | G17: NIC-00035976 | H17: 45686 | I17: GASTOS BANCARIOS 27 AL 31 DICIEMBRE 2024 -BGTA CALI | J17: DEVOLUCION DE DSF 1059-1060-1061 - GASTOS BANCARIOS 27 AL 31 DIC 2024 | K17: BANCO DE BOGOTA | M17: DSF | O17: =+MONTH(H17) -> 1 | P17: =+VLOOKUP(O17,X:Y,2,0) -> Enero
C18: 5502 - COMISIONES | D18: 53051501 | E18: COMISIONES BANCARIAS | F18: -78520 | G18: NIC-00035976 | H18: 45686 | I18: GASTOS BANCARIOS 27 AL 31 DICIEMBRE 2024 -BGTA TULUA | J18: DEVOLUCION DE DSF 1059-1060-1061 - GASTOS BANCARIOS 27 AL 31 DIC 2024 | K18: BANCO DE BOGOTA | M18: DSF | O18: =+MONTH(H18) -> 1 | P18: =+VLOOKUP(O18,X:Y,2,0) -> Enero
C19: 5502 - COMISIONES | D19: 53051501 | E19: COMISIONES BANCARIAS | F19: -2500 | G19: NIC-00035976 | H19: 45686 | I19: GASTOS BANCARIOS 27 AL 31 DICIEMBRE 2024 -POPULAR 2276 | J19: DEVOLUCION DE DSF 1059-1060-1061 - GASTOS BANCARIOS 27 AL 31 DIC 2024 | K19: BANCO POPULAR | M19: DSF | O19: =+MONTH(H19) -> 1 | P19: =+VLOOKUP(O19,X:Y,2,0) -> Enero
C20: 5502 - COMISIONES | D20: 53051501 | E20: COMISIONES BANCARIAS | F20: 3529 | G20: NIP-00016610 | H20: 45686 | I20: contabilización de iva comision 4*1000 | J20: contabilización de iva comision 4*1000 | K20: BANCOLOMBIA | M20: DSF | O20: =+MONTH(H20) -> 1 | P20: =+VLOOKUP(O20,X:Y,2,0) -> Enero
C21: 5502 - COMISIONES | D21: 53051501 | E21: COMISIONES BANCARIAS | F21: 3558750 | G21: FAC-00045087 | H21: 45688 | I21: FAC132801 - COMISION FIDUCIARIA MES DE ENERO 2025- COMISION FIJA 2.5 SMMLV | J21: FAC132801 - COMISION FIDUCIARIA MES DE ENERO 2025- COMISION FIJA 2.5 SMMLV | K21: FIDUCIARIA POPULAR S.A. | M21: DSF | O21: =+MONTH(H21) -> 1 | P21: =+VLOOKUP(O21,X:Y,2,0) -> Enero
C22: 5502 - COMISIONES | D22: 53051501 | E22: COMISIONES BANCARIAS | F22: 3558750 | G22: FAC-00045088 | H22: 45688 | I22: SOC81109 - COMISION POR ADMINISTRACION MES DE ENERO 2025 - EA | J22: SOC81109 - COMISION POR ADMINISTRACION MES DE ENERO 2025 - EA | K22: FIDUCIARIA DAVIVIENDA S.A | M22: DSF | O22: =+MONTH(H22) -> 1 | P22: =+VLOOKUP(O22,X:Y,2,0) -> Enero
C23: 5502 - COMISIONES | D23: 53051501 | E23: COMISIONES BANCARIAS | F23: 9600.49 | G23: NIB-00005875 | H23: 45688 | I23: COSTO DE TRANSACCION -PAGO DE FACTURAS A NOMBRE DE INGENIERIA Y EQUIPOS PARA LA INGENIERIA | J23: PAGO DE FACTURAS A NOMBRE DE INGENIERIA Y EQUIPOS PARA LA INGENIERIA | K23: BANCOLOMBIA | M23: DSF | O23: =+MONTH(H23) -> 1 | P23: =+VLOOKUP(O23,X:Y,2,0) -> Enero
C24: 5502 - COMISIONES | D24: 53051501 | E24: COMISIONES BANCARIAS | F24: 1824 | G24: NIB-00005875 | H24: 45688 | I24: IVA DE TRANSACCION -PAGO DE FACTURAS A NOMBRE DE INGENIERIA Y EQUIPOS PARA LA INGENIERIA | J24: PAGO DE FACTURAS A NOMBRE DE INGENIERIA Y EQUIPOS PARA LA INGENIERIA | K24: BANCOLOMBIA | O24: =+MONTH(H24) -> 1 | P24: =+VLOOKUP(O24,X:Y,2,0) -> Enero
C25: 5502 - COMISIONES | D25: 53051501 | E25: COMISIONES BANCARIAS | F25: 3867500 | G25: NIB-00005899 | H25: 45688 | I25: COMISION FIJA MES DE ENERO 2025 | J25: GASTOS BANCARIOS MES DE ENERO 2025 FIDEICOMISO 42112858 - RENTA LIQUIDAN GASTOS BANCARIOS MES DE ENERO 2025 FIDEICOMISO 42112858 - RENTA LIQUIDA | K25: FIDUCIARIA DAVIVIENDA S.A | O25: =+MONTH(H25) -> 1 | P25: =+VLOOKUP(O25,X:Y,2,0) -> Enero
C26: 5502 - COMISIONES | D26: 53051501 | E26: COMISIONES BANCARIAS | F26: 514829.43 | G26: NIB-00005902 | H26: 45688 | I26: GASTOS BANCARIOS MES DE ENERO 2025- BANCOLOMBIA PANAMA | J26: GASTOS BANCARIOS MES DE ENERO 2025- BANCOLOMBIA PANAMA | K26: BANCOLOMBIA PANAMA | O26: =+MONTH(H26) -> 1 | P26: =+VLOOKUP(O26,X:Y,2,0) -> Enero
C27: 5502 - COMISIONES | D27: 53051501 | E27: COMISIONES BANCARIAS | F27: 4280613 | G27: NIB-00005906 | H27: 45688 | I27: GASTOS BANCARIOS BOGOTA TULUA 612036319- MES DE ENERO 2025 | J27: GASTOS BANCARIOS BOGOTA TULUA 612036319- MES DE ENERO 2025 | K27: BANCO DE BOGOTA | O27: =+MONTH(H27) -> 1 | P27: =+VLOOKUP(O27,X:Y,2,0) -> Enero
C28: 5502 - COMISIONES | D28: 53051501 | E28: COMISIONES BANCARIAS | F28: 4700320.5 | G28: NIB-00005911 | H28: 45688 | I28: GASTOS BANCARIOS BANCOLOMBIA CTA CTE 80104152201 - MES DE ENERO 2025 | J28: GASTOS BANCARIOS BANCOLOMBIA CTA CTE 80104152201 - MES DE ENERO 2025 | K28: BANCOLOMBIA | O28: =+MONTH(H28) -> 1 | P28: =+VLOOKUP(O28,X:Y,2,0) -> Enero
C29: 5502 - COMISIONES | D29: 53051501 | E29: COMISIONES BANCARIAS | F29: 9801719 | G29: NIB-00005919 | H29: 45688 | I29: GASTOS BANCARIOS DAVIVIENDA 7678 MES DE ENERO 2025 | J29: GASTOS BANCARIOS DAVIVIENDA 7678 MES DE ENERO 2025 | K29: BANCO DAVIVIENDA S.A | O29: =+MONTH(H29) -> 1 | P29: =+VLOOKUP(O29,X:Y,2,0) -> Enero
C30: 5502 - COMISIONES | D30: 53051501 | E30: COMISIONES BANCARIAS | F30: 22436 | G30: NIB-00005936 | H30: 45688 | I30: GASTOS BANCARIOS BGTA CALI 256096355 MES DE ENERO 2025 | J30: GASTOS BANCARIOS BGTA CALI 256096355 MES DE ENERO 2025 | K30: BANCO DE BOGOTA | O30: =+MONTH(H30) -> 1 | P30: =+VLOOKUP(O30,X:Y,2,0) -> Enero
C31: 5502 - COMISIONES | D31: 53051502 | E31: COMISIONES POR FACTORING | F31: 7087724.8 | G31: NIC-00036152 | H31: 45688 | I31: COMISIONES FACTORIGN TRULULU FAN-28253-255 SUPER ALIMENTOS 28207-225-261-262 | J31: reclasificacion de cuentas en comision Factoring con Bavaria y Trululu | K31: BBVA COLOMBIA S.A. | O31: =+MONTH(H31) -> 1 | P31: =+VLOOKUP(O31,X:Y,2,0) -> Enero
C32: 5502 - COMISIONES | D32: 53051502 | E32: COMISIONES POR FACTORING | F32: 36839957 | G32: NIC-00036152 | H32: 45688 | I32: REGISTRO COMISION FACTORING BBVA FAN-27806-848-849-850-862-863-864 | J32: reclasificacion de cuentas en comision Factoring con Bavaria y Trululu | K32: BBVA COLOMBIA S.A. | O32: =+MONTH(H32) -> 1 | P32: =+VLOOKUP(O32,X:Y,2,0) -> Enero
C33: 5502 - COMISIONES | D33: 53051501 | E33: COMISIONES BANCARIAS | F33: 3529 | G33: NIC-00036050 | H33: 45692 | I33: CONTABILIZACIÓN IVA COMISION 4*1000 | J33: CONTABILIZACIÓN IVA COMISION 4*1000 | K33: BANCOLOMBIA | O33: =+MONTH(H33) -> 2 | P33: =+VLOOKUP(O33,X:Y,2,0) -> Febrero
C34: 5502 - COMISIONES | D34: 53051501 | E34: COMISIONES BANCARIAS | F34: 3529 | G34: NIC-00036051 | H34: 45692 | I34: CONTABILIZACIÓN IVA COMISION 4*1000 | J34: CONTABILIZACIÓN IVA COMISON 4*1000 | K34: BANCOLOMBIA | O34: =+MONTH(H34) -> 2 | P34: =+VLOOKUP(O34,X:Y,2,0) -> Febrero
C35: 5502 - COMISIONES | D35: 53051501 | E35: COMISIONES BANCARIAS | F35: 3529 | G35: NIC-00036053 | H35: 45692 | I35: CONTABILIZACIÓN IVA COMISION 4*1000 | J35: CONTABILIZACION IVA COMISON 4*1000 | K35: BANCOLOMBIA | O35: =+MONTH(H35) -> 2 | P35: =+VLOOKUP(O35,X:Y,2,0) -> Febrero
... C132: 5502 - COMISIONES | D132: 53051501 | E132: COMISIONES EN BOLSA | F132: 4782185 | G132: NIP-00016935 | H132: 45747 | I132: CLFV21376 - SERV REGISTRADO BMC 8600071250 | J132: CLFV21376 - SERV REGISTRADO BMC 8600071250 | K132: CORREAGRO S.A. | O132: =+MONTH(H132) -> 3 | P132: =+VLOOKUP(O132,X:Y,2,0) -> Marzo
C133: 5502 - COMISIONES | D133: 53051501 | E133: COMISIONES BANCARIAS | F133: 3529 | G133: NIP-00016938 | H133: 45749 | I133: CONTABILIZACIÓN IVA COMISION 4*1000 | J133: CONTABILIZACIÓN IVA COMISION 4*1000 | K133: BANCOLOMBIA | M133: DSF | O133: =+MONTH(H133) -> 4 | P133: =+VLOOKUP(O133,X:Y,2,0) -> Abril
C134: 5502 - COMISIONES | D134: 53051501 | E134: COMISIONES BANCARIAS | F134: 3529 | G134: NIP-00016939 | H134: 45749 | I134: CONTABILIZACIÓN IVA COMISION 4*1000 | J134: CONTABILIZACIÓN IVA COMISION 4*1000 | K134: BANCOLOMBIA | M134: DSF | O134: =+MONTH(H134) -> 4 | P134: =+VLOOKUP(O134,X:Y,2,0) -> Abril
C135: 5502 - COMISIONES | D135: 53051501 | E135: COMISIONES BANCARIAS | F135: 3529 | G135: NIP-00016940 | H135: 45749 | I135: CONTABILIZACIÓN IVA COMISION 4*1000 | J135: CONTABILIZACIÓN IVA COMISION 4*1000 | K135: BANCOLOMBIA | M135: DSF | O135: =+MONTH(H135) -> 4 | P135: =+VLOOKUP(O135,X:Y,2,0) -> Abril
C136: 5502 - COMISIONES | D136: 53051501 | E136: COMISIONES BANCARIAS | F136: 13140 | G136: NIB-00006418 | H136: 45754 | I136: PAGO DE DEPOSITOS JUDICIALES ICSA - SECUENCIAL ARCHIVO: 1513049 - GD2025040708891900196 - 30030 | J136: PAGO DE DEPOSITOS JUDICIALES ICSA - SECUENCIAL ARCHIVO: 1513049 - GD2025040708891900196 - 30030 | K136: BANCO AGRARIO DE COLOMBIA S.A | M136: DSF | O136: =+MONTH(H136) -> 4 | P136: =+VLOOKUP(O136,X:Y,2,0) -> Abril
...

Sheet COMISIONES
A1: CUENTA | B1: Auxiliar | C1: Desc. auxiliar | D1: Débitos | E1: Créditos | F1: Neto | G1: C.Costo | H1: Desc. C.Costo | I1: SECCION | J1: Fecha | K1: Docto. | L1: Notas | M1: Notas docto | N1: Nit tercero | O1: Razón social tercero docto. | P1: Nit movto. | Q1: Razón social tercero movto. | R1: Referencia 1 | S1: Referencia 2 | T1: Referencia 3 | U1: SUB SUBCUENTA | V1: Prefijo tipo docto | W1: Mes | X1: Nombre Mes
A2: 5502 - COMISIONES | B2: 53051501 | C2: BANCOS COMISIONES | D2: 2190 | E2: 0 | F2: 2190 | J2: 45664 | K2: NIB-00005736 | L2: PAGO DE DEPOSITOS JUDICIALES - COMPROBANTE DE PAGO: 1491465 - ARCHIVO: 30030 - INGENIO CARMELITA - ARCHIVO: GD20250107018919001961 | M2: PAGO DE DEPOSITOS JUDICIALES - COMPROBANTE DE PAGO: 1491465 - ARCHIVO: 30030 - INGENIO CARMELITA - ARCHIVO: GD20250107018919001961 | N2: 899999047 | O2: BANCO AGRARIO DE COLOMBIA | P2: 899999047 | Q2: BANCO AGRARIO DE COLOMBIA | W2: =+MONTH(J2) -> 1 | X2: =+ VLOOKUP(W2,'COMISIONES ENERO-MARZO 2025 (2)'!X:Y,2,0) -> Enero
A3: 5502 - COMISIONES | B3: 53051501 | C3: BANCOS COMISIONES | D3: 3529 | E3: 0 | F3: 3529 | J3: 45665 | K3: NIP-00016497 | L3: CONTABILIZACIÓN IVA COMISON 4*1000 | M3: CONTABILIZACIÓN IVA COMISON 4*1000 | N3: 16502466 | O3: SANTACRUZ JOHN | P3: 890903938 | Q3: BANCOLOMBIA | W3: =+MONTH(J3) -> 1 | X3: =+ VLOOKUP(W3,'COMISIONES ENERO-MARZO 2025 (2)'!X:Y,2,0) -> Enero
A4: 5502 - COMISIONES | B4: 53051501 | C4: BANCOS COMISIONES | D4: 7058 | E4: 0 | F4: 7058 | J4: 45665 | K4: NIP-00016498 | L4: CONTABILIZACIÓN IVA COMISON 4*1000 | M4: CONTABILIZACIÓN IVA COMISON 4*1000 | N4: 29760690 | O4: MORIONES SUAREZ BEATRIZ EUGENIA | P4: 890903938 | Q4: BANCOLOMBIA | W4: =+MONTH(J4) -> 1 | X4: =+ VLOOKUP(W4,'COMISIONES ENERO-MARZO 2025 (2)'!X:Y,2,0) -> Enero
A5: 5502 - COMISIONES | B5: 53051501 | C5: BANCOS COMISIONES | D5: 3529 | E5: 0 | F5: 3529 | J5: 45671 | K5: NIP-00016519 | L5: CONTABILIZACIÓN IVA COMISION 4*1000 | M5: CONTABILIZACIÓN IVA COMISION 4*1000 | N5: 16502466 | O5: SANTACRUZ JOHN | P5: 890903938 | Q5: BANCOLOMBIA | W5: =+MONTH(J5) -> 1 | X5: =+ VLOOKUP(W5,'COMISIONES ENERO-MARZO 2025 (2)'!X:Y,2,0) -> Enero
A6: 5502 - COMISIONES | B6: 53051501 | C6: BANCOS COMISIONES | D6: 2650 | E6: 0 | F6: 2650 | J6: 45674 | K6: NIB-00005915 | L6: GASTOS BANCARIOS POPULAR 2276 MES DE ENERO 2025 | M6: GASTOS BANCARIOS POPULAR 2276 MES DE ENERO 2025 | N6: 860007738 | O6: BANCO POPULAR | P6: 860007738 | Q6: BANCO POPULAR | W6: =+MONTH(J6) -> 1 | X6: =+ VLOOKUP(W6,'COMISIONES ENERO-MARZO 2025 (2)'!X:Y,2,0) -> Enero
A7: 5502 - COMISIONES | B7: 53051501 | C7: BANCOS COMISIONES | D7: 3529 | E7: 0 | F7: 3529 | J7: 45678 | K7: NIP-00016556 | L7: CONTAN¿BILIZACIÓN IVA 4*1000 COMISION | M7: CONTAN¿BILIZACIÓN IVA 4*1000 COMISION | N7: 16502466 | O7: SANTACRUZ JOHN | P7: 890903938 | Q7: BANCOLOMBIA | W7: =+MONTH(J7) -> 1 | X7: =+ VLOOKUP(W7,'COMISIONES ENERO-MARZO 2025 (2)'!X:Y,2,0) -> Enero
A8: 5502 - COMISIONES | B8: 53051501 | C8: BANCOS COMISIONES | D8: 3529 | E8: 0 | F8: 3529 | J8: 45679 | K8: NIP-00016562 | L8: contabilización iva comision 4*1000 | M8: contabilización iva comision 4*1000 | N8: 1112300106 | O8: NINO PALOMINO CARLOS MARIO | P8: 890903938 | Q8: BANCOLOMBIA | W8: =+MONTH(J8) -> 1 | X8: =+ VLOOKUP(W8,'COMISIONES ENERO-MARZO 2025 (2)'!X:Y,2,0) -> Enero
A9: 5502 - COMISIONES | B9: 53051501 | C9: BANCOS COMISIONES | D9: 3529 | E9: 0 | F9: 3529 | J9: 45684 | K9: NIP-00016588 | L9: CONTABILIZACIÓN IVA COMISION 4*1000 | M9: CONTABILIZACIÓN IVA COMISION 4*1000 | N9: 1144185697 | O9: REYES MORIONES ANGELICA | P9: 890903938 | Q9: BANCOLOMBIA | W9: =+MONTH(J9) -> 1 | X9: =+ VLOOKUP(W9,'COMISIONES ENERO-MARZO 2025 (2)'!X:Y,2,0) -> Enero
A10: 5502 - COMISIONES | B10: 53051501 | C10: BANCOS COMISIONES | D10: 38140 | E10: 0 | F10: 38140 | J10: 45686 | K10: DSF-00001059 | L10: GASTOS BANCARIOS 27 AL 31 DICIEMBRE 2024 -BGTA CALI | M10: GASTOS BANCARIOS 27 AL 31 DICIEMBRE 2024 | N10: 860002964 | O10: BANCO DE BOGOTA | P10: 860002964 | Q10: BANCO DE BOGOTA | V10: DSF | W10: =+MONTH(J10) -> 1 | X10: =+ VLOOKUP(W10,'COMISIONES ENERO-MARZO 2025 (2)'!X:Y,2,0) -> Enero
A11: 5502 - COMISIONES | B11: 53051501 | C11: BANCOS COMISIONES | D11: 78520 | E11: 0 | F11: 78520 | J11: 45686 | K11: DSF-00001059 | L11: GASTOS BANCARIOS 27 AL 31 DICIEMBRE 2024 -BGTA TULUA | M11: GASTOS BANCARIOS 27 AL 31 DICIEMBRE 2024 | N11: 860002964 | O11: BANCO DE BOGOTA | P11: 860002964 | Q11: BANCO DE BOGOTA | V11: DSF | W11: =+MONTH(J11) -> 1 | X11: =+ VLOOKUP(W11,'COMISIONES ENERO-MARZO 2025 (2)'!X:Y,2,0) -> Enero
A12: 5502 - COMISIONES | B12: 53051501 | C12: BANCOS COMISIONES | D12: 2500 | E12: 0 | F12: 2500 | J12: 45686 | K12: DSF-00001060 | L12: GASTOS BANCARIOS 27 AL 31 DICIEMBRE 2024 -POPULAR 2276 | M12: GASTOS BANCARIOS 27 AL 31 DICIEMBRE 2024 -POPULAR 2276 | N12: 860007738 | O12: BANCO POPULAR | P12: 860007738 | Q12: BANCO POPULAR | V12: DSF | W12: =+MONTH(J12) -> 1 | X12: =+ VLOOKUP(W12,'COMISIONES ENERO-MARZO 2025 (2)'!X:Y,2,0) -> Enero
A13: 5502 - COMISIONES | B13: 53051501 | C13: BANCOS COMISIONES | D13: 125906.09 | E13: 0 | F13: 125906.09 | J13: 45686 | K13: DSF-00001061 | L13: GASTOS BANCARIOS 27 AL 31 DICIEMBRE 2024 -BANCOLOMBIA 801 | M13: GASTOS BANCARIOS 27 AL 31 DICIEMBRE 2024 -BANCOLOMBIA | N13: 890903938 | O13: BANCOLOMBIA | P13: 890903938 | Q13: BANCOLOMBIA | V13: DSF | W13: =+MONTH(J13) -> 1 | X13: =+ VLOOKUP(W13,'COMISIONES ENERO-MARZO 2025 (2)'!X:Y,2,0) -> Enero
A14: 5502 - COMISIONES | B14: 53051501 | C14: BANCOS COMISIONES | D14: 16560 | E14: 0 | F14: 16560 | J14: 45686 | K14: DSF-00001061 | L14: GASTOS BANCARIOS 27 AL 31 DICIEMBRE 2024 -BANCOLOMBIA ESPECIAL | M14: GASTOS BANCARIOS 27 AL 31 DICIEMBRE 2024 -BANCOLOMBIA | N14: 890903938 | O14: BANCOLOMBIA | P14: 890903938 | Q14: BANCOLOMBIA | V14: DSF | W14: =+MONTH(J14) -> 1 | X14: =+ VLOOKUP(W14,'COMISIONES ENERO-MARZO 2025 (2)'!X:Y,2,0) -> Enero
A15: 5502 - COMISIONES | B15: 53051501 | C15: BANCOS COMISIONES | D15: 0 | E15: 125906.09 | F15: -125906.09 | J15: 45686 | K15: NIC-00035976 | L15: GASTOS BANCARIOS 27 AL 31 DICIEMBRE 2024 -BANCOLOMBIA 801 | M15: DEVOLUCION DE DSF 1059-1060-1061 - GASTOS BANCARIOS 27 AL 31 DIC 2024 | N15: 891900196 | O15: INGENIO CARMELITA S.A. | P15: 890903938 | Q15: BANCOLOMBIA | W15: =+MONTH(J15) -> 1 | X15: =+ VLOOKUP(W15,'COMISIONES ENERO-MARZO 2025 (2)'!X:Y,2,0) -> Enero
A16: 5502 - COMISIONES | B16: 53051501 | C16: BANCOS COMISIONES | D16: 0 | E16: 16560 | F16: -16560 | J16: 45686 | K16: NIC-00035976 | L16: GASTOS BANCARIOS 27 AL 31 DICIEMBRE 2024 -BANCOLOMBIA ESPECIAL | M16: DEVOLUCION DE DSF 1059-1060-1061 - GASTOS BANCARIOS 27 AL 31 DIC 2024 | N16: 891900196 | O16: INGENIO CARMELITA S.A. | P16: 890903938 | Q16: BANCOLOMBIA | W16: =+MONTH(J16) -> 1 | X16: =+ VLOOKUP(W16,'COMISIONES ENERO-MARZO 2025 (2)'!X:Y,2,0) -> Enero
A17: 5502 - COMISIONES | B17: 53051501 | C17: BANCOS COMISIONES | D17: 0 | E17: 38140 | F17: -38140 | J17: 45686 | K17: NIC-00035976 | L17: GASTOS BANCARIOS 27 AL 31 DICIEMBRE 2024 -BGTA CALI | M17: DEVOLUCION DE DSF 1059-1060-1061 - GASTOS BANCARIOS 27 AL 31 DIC 2024 | N17: 891900196 | O17: INGENIO CARMELITA S.A. | P17: 860002964 | Q17: BANCO DE BOGOTA | W17: =+MONTH(J17) -> 1 | X17: =+ VLOOKUP(W17,'COMISIONES ENERO-MARZO 2025 (2)'!X:Y,2,0) -> Enero
A18: 5502 - COMISIONES | B18: 53051501 | C18: BANCOS COMISIONES | D18: 0 | E18: 78520 | F18: -78520 | J18: 45686 | K18: NIC-00035976 | L18: GASTOS BANCARIOS 27 AL 31 DICIEMBRE 2024 -BGTA TULUA | M18: DEVOLUCION DE DSF 1059-1060-1061 - GASTOS BANCARIOS 27 AL 31 DIC 2024 | N18: 891900196 | O18: INGENIO CARMELITA S.A. | P18: 860002964 | Q18: BANCO DE BOGOTA | W18: =+MONTH(J18) -> 1 | X18: =+ VLOOKUP(W18,'COMISIONES ENERO-MARZO 2025 (2)'!X:Y,2,0) -> Enero
A19: 5502 - COMISIONES | B19: 53051501 | C19: BANCOS COMISIONES | D19: 0 | E19: 2500 | F19: -2500 | J19: 45686 | K19: NIC-00035976 | L19: GASTOS BANCARIOS 27 AL 31 DICIEMBRE 2024 -POPULAR 2276 | M19: DEVOLUCION DE DSF 1059-1060-1061 - GASTOS BANCARIOS 27 AL 31 DIC 2024 | N19: 891900196 | O19: INGENIO CARMELITA S.A. | P19: 860007738 | Q19: BANCO POPULAR | W19: =+MONTH(J19) -> 1 | X19: =+ VLOOKUP(W19,'COMISIONES ENERO-MARZO 2025 (2)'!X:Y,2,0) -> Enero
A20: 5502 - COMISIONES | B20: 53051501 | C20: BANCOS COMISIONES | D20: 3529 | E20: 0 | F20: 3529 | J20: 45686 | K20: NIP-00016610 | L20: contabilización de iva comision 4*1000 | M20: contabilización de iva comision 4*1000 | N20: 16502466 | O20: SANTACRUZ JOHN | P20: 890903938 | Q20: BANCOLOMBIA | W20: =+MONTH(J20) -> 1 | X20: =+ VLOOKUP(W20,'COMISIONES ENERO-MARZO 2025 (2)'!X:Y,2,0) -> Enero
A21: 5502 - COMISIONES | B21: 53051501 | C21: BANCOS COMISIONES | D21: 3558750 | E21: 0 | F21: 3558750 | J21: 45688 | K21: FAC-00045087 | L21: FAC132801 - COMISION FIDUCIARIA MES DE ENERO 2025- COMISION FIJA 2.5 SMMLV | M21: FAC132801 - COMISION FIDUCIARIA MES DE ENERO 2025- COMISION FIJA 2.5 SMMLV | N21: 800141235 | O21: FIDUCIARIA POPULAR S.A. | P21: 800141235 | Q21: FIDUCIARIA POPULAR S.A. | W21: =+MONTH(J21) -> 1 | X21: =+ VLOOKUP(W21,'COMISIONES ENERO-MARZO 2025 (2)'!X:Y,2,0) -> Enero
A22: 5502 - COMISIONES | B22: 53051501 | C22: BANCOS COMISIONES | D22: 3558750 | E22: 0 | F22: 3558750 | J22: 45688 | K22: FAC-00045088 | L22: SOC81109 - COMISION POR ADMINISTRACION MES DE ENERO 2025 - EA | M22: SOC81109 - COMISION POR ADMINISTRACION MES DE ENERO 2025 - EA | N22: 800182281 | O22: FIDUCIARIA DAVIVIENDA S.A | P22: 800182281 | Q22: FIDUCIARIA DAVIVIENDA S.A | W22: =+MONTH(J22) -> 1 | X22: =+ VLOOKUP(W22,'COMISIONES ENERO-MARZO 2025 (2)'!X:Y,2,0) -> Enero
A23: 5502 - COMISIONES | B23: 53051501 | C23: BANCOS COMISIONES | D23: 9600.49 | E23: 0 | F23: 9600.49 | J23: 45688 | K23: NIB-00005875 | L23: COSTO DE TRANSACCION -PAGO DE FACTURAS A NOMBRE DE INGENIERIA Y EQUIPOS PARA LA INGENIERIA | M23: PAGO DE FACTURAS A NOMBRE DE INGENIERIA Y EQUIPOS PARA LA INGENIERIA | N23: 890903938 | O23: BANCOLOMBIA | P23: 890903938 | Q23: BANCOLOMBIA | W23: =+MONTH(J23) -> 1 | X23: =+ VLOOKUP(W23,'COMISIONES ENERO-MARZO 2025 (2)'!X:Y,2,0) -> Enero
A24: 5502 - COMISIONES | B24: 53051501 | C24: BANCOS COMISIONES | D24: 1824 | E24: 0 | F24: 1824 | J24: 45688 | K24: NIB-00005875 | L24: IVA DE TRANSACCION -PAGO DE FACTURAS A NOMBRE DE INGENIERIA Y EQUIPOS PARA LA INGENIERIA | M24: PAGO DE FACTURAS A NOMBRE DE INGENIERIA Y EQUIPOS PARA LA INGENIERIA | N24: 890903938 | O24: BANCOLOMBIA | P24: 890903938 | Q24: BANCOLOMBIA | W24: =+MONTH(J24) -> 1 | X24: =+ VLOOKUP(W24,'COMISIONES ENERO-MARZO 2025 (2)'!X:Y,2,0) -> Enero
A25: 5502 - COMISIONES | B25: 53051501 | C25: BANCOS COMISIONES | D25: 3867500 | E25: 0 | F25: 3867500 | J25: 45688 | K25: NIB-00005899 | L25: COMISION FIJA MES DE ENERO 2025 | M25: GASTOS BANCARIOS MES DE ENERO 2025 FIDEICOMISO 42112858 - RENTA LIQUIDAN GASTOS BANCARIOS MES DE ENERO 2025 FIDEICOMISO 42112858 - RENTA LIQUIDA | N25: 800182281 | O25: FIDUCIARIA DAVIVIENDA S.A | P25: 800182281 | Q25: FIDUCIARIA DAVIVIENDA S.A | W25: =+MONTH(J25) -> 1 | X25: =+ VLOOKUP(W25,'COMISIONES ENERO-MARZO 2025 (2)'!X:Y,2,0) -> Enero
A26: 5502 - COMISIONES | B26: 53051501 | C26: BANCOS COMISIONES | D26: 514829.43 | E26: 0 | F26: 514829.43 | J26: 45688 | K26: NIB-00005902 | L26: GASTOS BANCARIOS MES DE ENERO 2025- BANCOLOMBIA PANAMA | M26: GASTOS BANCARIOS MES DE ENERO 2025- BANCOLOMBIA PANAMA | N26: 928149105971DV28 | O26: BANCOLOMBIA PANAMA | P26: 928149105971DV28 | Q26: BANCOLOMBIA PANAMA | W26: =+MONTH(J26) -> 1 | X26: =+ VLOOKUP(W26,'COMISIONES ENERO-MARZO 2025 (2)'!X:Y,2,0) -> Enero
A27: 5502 - COMISIONES | B27: 53051501 | C27: BANCOS COMISIONES | D27: 4280613 | E27: 0 | F27: 4280613 | J27: 45688 | K27: NIB-00005906 | L27: GASTOS BANCARIOS BOGOTA TULUA 612036319- MES DE ENERO 2025 | M27: GASTOS BANCARIOS BOGOTA TULUA 612036319- MES DE ENERO 2025 | N27: 860002964 | O27: BANCO DE BOGOTA | P27: 860002964 | Q27: BANCO DE BOGOTA | W27: =+MONTH(J27) -> 1 | X27: =+ VLOOKUP(W27,'COMISIONES ENERO-MARZO 2025 (2)'!X:Y,2,0) -> Enero
A28: 5502 - COMISIONES | B28: 53051501 | C28: BANCOS COMISIONES | D28: 4700320.5 | E28: 0 | F28: 4700320.5 | J28: 45688 | K28: NIB-00005911 | L28: GASTOS BANCARIOS BANCOLOMBIA CTA CTE 80104152201 - MES DE ENERO 2025 | M28: GASTOS BANCARIOS BANCOLOMBIA CTA CTE 80104152201 - MES DE ENERO 2025 | N28: 890903938 | O28: BANCOLOMBIA | P28: 890903938 | Q28: BANCOLOMBIA | W28: =+MONTH(J28) -> 1 | X28: =+ VLOOKUP(W28,'COMISIONES ENERO-MARZO 2025 (2)'!X:Y,2,0) -> Enero
A29: 5502 - COMISIONES | B29: 53051501 | C29: BANCOS COMISIONES | D29: 9801719 | E29: 0 | F29: 9801719 | J29: 45688 | K29: NIB-00005919 | L29: GASTOS BANCARIOS DAVIVIENDA 7678 MES DE ENERO 2025 | M29: GASTOS BANCARIOS DAVIVIENDA 7678 MES DE ENERO 2025 | N29: 860034313 | O29: DAVIVIENDA | P29: 860034313 | Q29: DAVIVIENDA | W29: =+MONTH(J29) -> 1 | X29: =+ VLOOKUP(W29,'COMISIONES ENERO-MARZO 2025 (2)'!X:Y,2,0) -> Enero
A30: 5502 - COMISIONES | B30: 53051501 | C30: BANCOS COMISIONES | D30: 22436 | E30: 0 | F30: 22436 | J30: 45688 | K30: NIB-00005936 | L30: GASTOS BANCARIOS BGTA CALI 256096355 MES DE ENERO 2025 | M30: GASTOS BANCARIOS BGTA CALI 256096355 MES DE ENERO 2025 | N30: 860002964 | O30: BANCO DE BOGOTA | P30: 860002964 | Q30: BANCO DE BOGOTA | W30: =+MONTH(J30) -> 1 | X30: =+ VLOOKUP(W30,'COMISIONES ENERO-MARZO 2025 (2)'!X:Y,2,0) -> Enero
A31: 5502 - COMISIONES | B31: 53051501 | C31: BANCOS COMISIONES | D31: 7087724.8 | E31: 0 | F31: 7087724.8 | J31: 45688 | K31: NIC-00036152 | L31: COMISIONES FACTORIGN TRULULU FAN-28253-255 SUPER ALIMENTOS 28207-225-261-262 | M31: reclasificacion de cuentas en comision Factoring con Bavaria y Trululu | N31: 860003020 | O31: BBVA COLOMBIA S.A. | P31: 860003020 | Q31: BBVA COLOMBIA S.A. | W31: =+MONTH(J31) -> 1 | X31: =+ VLOOKUP(W31,'COMISIONES ENERO-MARZO 2025 (2)'!X:Y,2,0) -> Enero
A32: 5502 - COMISIONES | B32: 53051501 | C32: BANCOS COMISIONES | D32: 36839957 | E32: 0 | F32: 36839957 | J32: 45688 | K32: NIC-00036152 | L32: REGISTRO COMISION FACTORING BBVA FAN-27806-848-849-850-862-863-864 | M32: reclasificacion de cuentas en comision Factoring con Bavaria y Trululu | N32: 860003020 | O32: BBVA COLOMBIA S.A. | P32: 860003020 | Q32: BBVA COLOMBIA S.A. | W32: =+MONTH(J32) -> 1 | X32: =+ VLOOKUP(W32,'COMISIONES ENERO-MARZO 2025 (2)'!X:Y,2,0) -> Enero
A33: 5502 - COMISIONES | B33: 53051501 | C33: BANCOS COMISIONES | D33: 3529 | E33: 0 | F33: 3529 | J33: 45692 | K33: NIC-00036050 | L33: CONTABILIZACIÓN IVA COMISION 4*1000 | M33: CONTABILIZACIÓN IVA COMISION 4*1000 | N33: 29760690 | O33: MORIONES SUAREZ BEATRIZ EUGENIA | P33: 890903938 | Q33: BANCOLOMBIA | W33: =+MONTH(J33) -> 2 | X33: =+ VLOOKUP(W33,'COMISIONES ENERO-MARZO 2025 (2)'!X:Y,2,0) -> Febrero
A34: 5502 - COMISIONES | B34: 53051501 | C34: BANCOS COMISIONES | D34: 3529 | E34: 0 | F34: 3529 | J34: 45692 | K34: NIC-00036051 | L34: CONTABILIZACIÓN IVA COMISION 4*1000 | M34: CONTABILIZACIÓN IVA COMISON 4*1000 | N34: 16502466 | O34: SANTACRUZ JOHN | P34: 890903938 | Q34: BANCOLOMBIA | W34: =+MONTH(J34) -> 2 | X34: =+ VLOOKUP(W34,'COMISIONES ENERO-MARZO 2025 (2)'!X:Y,2,0) -> Febrero
A35: 5502 - COMISIONES | B35: 53051501 | C35: BANCOS COMISIONES | D35: 3529 | E35: 0 | F35: 3529 | J35: 45692 | K35: NIC-00036053 | L35: CONTABILIZACIÓN IVA COMISION 4*1000 | M35: CONTABILIZACION IVA COMISON 4*1000 | N35: 1144185697 | O35: REYES MORIONES ANGELICA | P35: 890903938 | Q35: BANCOLOMBIA | W35: =+MONTH(J35) -> 2 | X35: =+ VLOOKUP(W35,'COMISIONES ENERO-MARZO 2025 (2)'!X:Y,2,0) -> Febrero
A36: 5502 - COMISIONES | B36: 53051501 | C36: BANCOS COMISIONES | D36: 11004 | E36: 0 | F36: 11004 | J36: 45695 | K36: NIB-00005978 | L36: PAGO DE DEPOSITOS JUCIALES ICSA - 1499295 - SECUENCIAL DEL ARCHIVO: GD202502070891001961_01.TXT | M36: PAGO DE DEPOSITOS JUCIALES ICSA - 1499295 - SECUENCIAL DEL ARCHIVO: GD202502070891001961_01.TXT | N36: 899999047 | O36: BANCO AGRARIO DE COLOMBIA | P36: 899999047 | Q36: BANCO AGRARIO DE COLOMBIA | W36: =+MONTH(J36) -> 2 | X36: =+ VLOOKUP(W36,'COMISIONES ENERO-MARZO 2025 (2)'!X:Y,2,0) -> Febrero
A37: 5502 - COMISIONES | B37: 53051501 | C37: BANCOS COMISIONES | D37: 9600 | E37: 0 | F37: 9600 | J37: 45702 | K37: NIB-00005995 | L37: PAGO DE DEPOSITOS JUDICIALES - INGENIERIA Y EQUIPOS PARA LA INDUSTRIA - CODIGO DEL JUZGADO 760012031004 - NUMEOR DE PROCESO 7600131030042023000800 | M37: PAGO DE DEPOSITOS JUDICIALES - INGENIERIA Y EQUIPOS PARA LA INDUSTRIA - CODIGO DEL JUZGADO 760012031004 - NUMEOR DE PROCESO 7600131030042023000800 | N37: 899999047 | O37: BANCO AGRARIO DE COLOMBIA | P37: 899999047 | Q37: BANCO AGRARIO DE COLOMBIA | W37: =+MONTH(J37) -> 2 | X37: =+ VLOOKUP(W37,'COMISIONES ENERO-MARZO 2025 (2)'!X:Y,2,0) -> Febrero
A38: 5502 - COMISIONES | B38: 53051501 | C38: BANCOS COMISIONES | D38: 3529 | E38: 0 | F38: 3529 | J38: 45702 | K38: NIP-00016714 | L38: CONTABILIZACIÓN IVA COMISION 4*1000 | M38: CONTABILIZACIÓN IVA COMISION 4*1000 | N38: 16502466 | O38: SANTACRUZ JOHN | P38: 890903938 | Q38: BANCOLOMBIA | W38: =+MONTH(J38) -> 2 | X38: =+ VLOOKUP(W38,'COMISIONES ENERO-MARZO 2025 (2)'!X:Y,2,0) -> Febrero
A39: 5502 - COMISIONES | B39: 53051501 | C39: BANCOS COMISIONES | D39: 3529 | E39: 0 | F39: 3529 | J39: 45706 | K39: NIP-00016723 | L39: CONTABILIZACIÓN IVA COMISON 4*1000 | M39: CONTABILIZACIÓN IVA COMISON 4*1000 | N39: 16502466 | O39: SANTACRUZ JOHN | P39: 890903938 | Q39: BANCOLOMBIA | W39: =+MONTH(J39) -> 2 | X39: =+ VLOOKUP(W39,'COMISIONES ENERO-MARZO 2025 (2)'!X:Y,2,0) -> Febrero
A40: 5502 - COMISIONES | B40: 53051501 | C40: BANCOS COMISIONES | D40: 4303049 | E40: 0 | F40: 4303049 | J40: 45707 | K40: DSF-00001074 | L40: GASTOS BANCARIOS CORRESPONDIENTES AL MES DE ENERO 2025 | M40: GASTOS BANCARIOS CORRESPONDIENTES AL MES DE ENERO 2025 | N40: 860002964 | O40: BANCO DE BOGOTA | P40: 860002964 | Q40: BANCO DE BOGOTA | V40: DSF | W40: =+MONTH(J40) -> 2 | X40: =+ VLOOKUP(W40,'COMISIONES ENERO-MARZO 2025 (2)'!X:Y,2,0) -> Febrero
...

Sheet 4 x 1000
A1: C.Costo | B1: Desc. C.Costo | C1: CUENTA | D1: Auxiliar | E1: Desc. auxiliar | F1: Neto | G1: Docto. | H1: Fecha | I1: Notas | J1: Notas docto | K1: Razón social tercero movto. | L1: SECCION | M1: Prefijo tipo docto | N1: SUB SUBCUENTA | O1: Mes | P1: Año | Q1: Nombre Mes
C2: 5305 - DEL SECTOR FINANCIERO | D2: 53059501 | E2: IMPUESTO 4 X 1.000 | F2: =-1679385527.54*0 -> 0 | G2: CCR-00000049 | H2: 45657 | I2: CIERRE CONTABLE Y FISCAL AÑO 2024 | J2: CIERRE CONTABLE Y FISCAL AÑO 2024 | K2: Genérico | O2: =+MONTH(H2) -> 12 | P2: =+YEAR(H2) -> 2024 | Q2: =+VLOOKUP(O2,'COMISIONES ENERO-MARZO 2025 (2)'!$X:$Y,2,0) -> Diciembre
C3: 5305 - DEL SECTOR FINANCIERO | D3: 53059501 | E3: IMPUESTO 4 X 1.000 | F3: 260 | G3: MBC-00000325 | H3: 45322 | I3: GASTOS FINANCIEROS MES DE ENERO DE 2023 | J3: GASTOS FINANCIEROS MES DE ENERO DE 2023 | K3: BANCO DE BOGOTA | O3: =+MONTH(H3) -> 1 | P3: =+YEAR(H3) -> 2024 | Q3: =+VLOOKUP(O3,'COMISIONES ENERO-MARZO 2025 (2)'!$X:$Y,2,0) -> Enero
C4: 5305 - DEL SECTOR FINANCIERO | D4: 53059501 | E4: IMPUESTO 4 X 1.000 | F4: 36467595 | G4: MBC-00000326 | H4: 45322 | I4: GASTOS FINANCIEROS MES DE ENERO DE 2024 BOGOTA TULUA | J4: GASTOS FINANCIEROS MES DE ENERO DE 2024 BOGOTA TULUA | K4: BANCO DE BOGOTA | O4: =+MONTH(H4) -> 1 | P4: =+YEAR(H4) -> 2024 | Q4: =+VLOOKUP(O4,'COMISIONES ENERO-MARZO 2025 (2)'!$X:$Y,2,0) -> Enero
C5: 5305 - DEL SECTOR FINANCIERO | D5: 53059501 | E5: IMPUESTO 4 X 1.000 | F5: 40513274 | G5: MBC-00000327 | H5: 45322 | I5: GASTOS FINANCIEROS MES DE ENERO DE 2024 BANCOLOMBIA 801 | J5: GASTOS FINANCIEROS MES DE ENERO DE 2024 BANCOLOMBIA 801 | K5: BANCOLOMBIA | O5: =+MONTH(H5) -> 1 | P5: =+YEAR(H5) -> 2024 | Q5: =+VLOOKUP(O5,'COMISIONES ENERO-MARZO 2025 (2)'!$X:$Y,2,0) -> Enero
C6: 5305 - DEL SECTOR FINANCIERO | D6: 53059501 | E6: IMPUESTO 4 X 1.000 | F6: 63537748 | G6: MBC-00000328 | H6: 45351 | I6: GAST¿OS FINANCIEROS MES DE FEBRERO DE 2024 BANCOLOMBIA 801 | J6: GAST¿OS FINANCIEROS MES DE FEBRERO DE 2024 BANCOLOMBIA 801 | K6: BANCOLOMBIA | O6: =+MONTH(H6) -> 2 | P6: =+YEAR(H6) -> 2024 | Q6: =+VLOOKUP(O6,'COMISIONES ENERO-MARZO 2025 (2)'!$X:$Y,2,0) -> Febrero
C7: 5305 - DEL SECTOR FINANCIERO | D7: 53059501 | E7: IMPUESTO 4 X 1.000 | F7: 306 | G7: MBC-00000329 | H7: 45351 | I7: GASTOS FINANCIEROS MES DE FEBRERO DE 2024 BOGOTA CALI | J7: GASTOS FINANCIEROS MES DE FEBRERO DE 2024 BOGOTA CALI | K7: BANCO DE BOGOTA | O7: =+MONTH(H7) -> 2 | P7: =+YEAR(H7) -> 2024 | Q7: =+VLOOKUP(O7,'COMISIONES ENERO-MARZO 2025 (2)'!$X:$Y,2,0) -> Febrero
C8: 5305 - DEL SECTOR FINANCIERO | D8: 53059501 | E8: IMPUESTO 4 X 1.000 | F8: 32900855 | G8: MBC-00000330 | H8: 45351 | I8: GASTOS FINANCIEROS MES DE FEBRERO DE 2024- BOGOTA TULUA | J8: GASTOS FINANCIEROS MES DE FEBRERO DE 2024- BOGOTA TULUA | K8: BANCO DE BOGOTA | O8: =+MONTH(H8) -> 2 | P8: =+YEAR(H8) -> 2024 | Q8: =+VLOOKUP(O8,'COMISIONES ENERO-MARZO 2025 (2)'!$X:$Y,2,0) -> Febrero
C9: 5305 - DEL SECTOR FINANCIERO | D9: 53059501 | E9: IMPUESTO 4 X 1.000 | F9: 36889004 | G9: MBC-00000331 | H9: 45382 | I9: GASTOS FINANCIEROS MES DE MARZO DE 2024 | J9: GASTOS FINANCIEROS MES DE MARZO DE 2024 | K9: BANCOLOMBIA | O9: =+MONTH(H9) -> 3 | P9: =+YEAR(H9) -> 2024 | Q9: =+VLOOKUP(O9,'COMISIONES ENERO-MARZO 2025 (2)'!$X:$Y,2,0) -> Marzo
C10: 5305 - DEL SECTOR FINANCIERO | D10: 53059501 | E10: IMPUESTO 4 X 1.000 | F10: 10258 | G10: MBC-00000332 | H10: 45382 | I10: GASTOS FINANCIEROS MES DE MARZO BOGOTA CALIO | J10: GASTOS FINANCIEROS MES DE MARZO BOGOTA CALIO | K10: BANCO DE BOGOTA | O10: =+MONTH(H10) -> 3 | P10: =+YEAR(H10) -> 2024 | Q10: =+VLOOKUP(O10,'COMISIONES ENERO-MARZO 2025 (2)'!$X:$Y,2,0) -> Marzo
C11: 5305 - DEL SECTOR FINANCIERO | D11: 53059501 | E11: IMPUESTO 4 X 1.000 | F11: 34084348 | G11: MBC-00000333 | H11: 45382 | I11: GASTOS FINANCIEROS MES DE MARZO DE 2024 BOGOTA TULUA | J11: GASTOS FINANCIEROS MES DE MARZO DE 2024 BOGOTA TULUA | K11: BANCO DE BOGOTA | O11: =+MONTH(H11) -> 3 | P11: =+YEAR(H11) -> 2024 | Q11: =+VLOOKUP(O11,'COMISIONES ENERO-MARZO 2025 (2)'!$X:$Y,2,0) -> Marzo
C12: 5305 - DEL SECTOR FINANCIERO | D12: 53059501 | E12: IMPUESTO 4 X 1.000 | F12: 44302453 | G12: MBC-00000334 | H12: 45412 | I12: GASTOS FINANCIEROS MES DE ABRL 2024 - BANCOLOMBIA 801 | J12: GASTOS FINANCIEROS MES DE ABRL 2024 - BANCOLOMBIA 801 | K12: BANCOLOMBIA | O12: =+MONTH(H12) -> 4 | P12: =+YEAR(H12) -> 2024 | Q12: =+VLOOKUP(O12,'COMISIONES ENERO-MARZO 2025 (2)'!$X:$Y,2,0) -> Abril
C13: 5305 - DEL SECTOR FINANCIERO | D13: 53059501 | E13: IMPUESTO 4 X 1.000 | F13: 306 | G13: MBC-00000335 | H13: 45412 | I13: GASTOS FINANCIEROS MES DE ABRIL BOGOTA 256 | J13: GASTOS FINANCIEROS MES DE ABRIL BOGOTA 256 | K13: BANCO DE BOGOTA | O13: =+MONTH(H13) -> 4 | P13: =+YEAR(H13) -> 2024 | Q13: =+VLOOKUP(O13,'COMISIONES ENERO-MARZO 2025 (2)'!$X:$Y,2,0) -> Abril
C14: 5305 - DEL SECTOR FINANCIERO | D14: 53059501 | E14: IMPUESTO 4 X 1.000 | F14: 32381690 | G14: MBC-00000336 | H14: 45412 | I14: GASTOS FINANCIEROS MES DE ABRIL BOGOTA TULUA | J14: GASTOS FINANCIEROS MES DE ABRIL BOGOTA TULUA | K14: BANCO DE BOGOTA | O14: =+MONTH(H14) -> 4 | P14: =+YEAR(H14) -> 2024 | Q14: =+VLOOKUP(O14,'COMISIONES ENERO-MARZO 2025 (2)'!$X:$Y,2,0) -> Abril
... C526: 5305 - DEL SECTOR FINANCIERO | D526: 53059501 | E526: IMPUESTO 4 X 1.000 | F526: 1851230.9 | G526: NIB-00008386 | H526: 46022 | I526: GASTOS BANCARIOS FONDO INVERSION RENTA L 482800029407 DAV MES DE DICIEMBRE 2025 | J526: GASTOS BANCARIOS FONDO INVERSION RENTA L 482800029407 DAV MES DE DICIEMBRE 2025 | K526: PATRIMONIOS AUTONOMOS ADMINISTRADOS POR LA SOC FIDUCIARIA DAVIVIENDA | O526: =+MONTH(H526) -> 12 | P526: =+YEAR(H526) -> 2025 | Q526: =+VLOOKUP(O526,'COMISIONES ENERO-MARZO 2025 (2)'!$X:$Y,2,0) -> Diciembre
C527: 5305 - DEL SECTOR FINANCIERO | D527: 53059501 | E527: IMPUESTO 4 X 1.000 | F527: 1433841 | G527: NIB-00008424 | H527: 46022 | I527: GASTOS BANCARIOS BANCO BBVA COLOMBIA CTE MES DE DICIEMBRE 2025 | J527: GASTOS BANCARIOS BANCO BBVA COLOMBIA CTE MES DE DICIEMBRE 2025 | K527: BBVA COLOMBIA S.A. | O527: 12 | P527: 2025 | Q527: Diciembre
C528: 5305 - DEL SECTOR FINANCIERO | D528: 53059501 | E528: IMPUESTO 4 X 1.000 | F528: 974938.82 | G528: NIB-00008368 | H528: 46022 | I528: GASTOS BANCARIOS BANCO POPULAR CTA CTE 110560212276 MES DE DICIEMBRE 2025 | J528: GASTOS BANCARIOS BANCO POPULAR CTA CTE 110560212276 MES DE DICIEMBRE 2025 | K528: BANCO POPULAR | O528: =+MONTH(H528) -> 12 | P528: =+YEAR(H528) -> 2025 | Q528: =+VLOOKUP(O528,'COMISIONES ENERO-MARZO 2025 (2)'!$X:$Y,2,0) -> Diciembre
C529: 5305 - DEL SECTOR FINANCIERO | D529: 53059501 | E529: IMPUESTO 4 X 1.000 | F529: =757704.24+29231.13 -> 786935.37 | G529: NIB-00008364 | H529: 46022 | I529: GASTOS BANCARIOS BANCOLOMBIA AHORRO 30631513979 | J529: GASTOS BANCARIOS BANCOLOMBIA AHORRO 30631513979 | K529: BANCOLOMBIA | O529: =+MONTH(H529) -> 12 | P529: =+YEAR(H529) -> 2025 | Q529: =+VLOOKUP(O529,'COMISIONES ENERO-MARZO 2025 (2)'!$X:$Y,2,0) -> Diciembre
C530: 5305 - DEL SECTOR FINANCIERO | D530: 53050501 | E530: GASTOS BANCARIOS | F530: 168067.23 | G530: NIB-00008326 | H530: 46006 | I530: FACTORING FAN-33227 COMISION PAGO | J530: FACTORING FAN-33227 COMISION PAGO | K530: KLYM S.A.S | O530: =+MONTH(H530) -> 12 | P530: =+YEAR(H530) -> 2025 | Q530: =+VLOOKUP(O530,'COMISIONES ENERO-MARZO 2025 (2)'!$X:$Y,2,0) -> Diciembre
C531: 5305 - DEL SECTOR FINANCIERO | D531: 53059501 | E531: IMPUESTO 4 X 1.000 | F531: 24471.84 | G531: NIB-00008366 | H531: 46022 | I531: GASTOS BANCARIOS BANCOLOMBIA SOBREGIRO 76282316703 MES DE DICIEMBRE 2025 | J531: GASTOS BANCARIOS BANCOLOMBIA SOBREGIRO 76282316703 MES DE DICIEMBRE 2025 | K531: BANCOLOMBIA | O531: =+MONTH(H531) -> 12 | P531: =+YEAR(H531) -> 2025 | Q531: =+VLOOKUP(O531,'COMISIONES ENERO-MARZO 2025 (2)'!$X:$Y,2,0) -> Diciembre
C532: 5305 - DEL SECTOR FINANCIERO | D532: 53059501 | E532: IMPUESTO 4 X 1.000 | F532: 23906 | G532: NIB-00008363 | H532: 46000 | I532: LEGALIZACION DE TC DESTINOS 4302840001596798 MES DE NOVIEMBRE 2025 | J532: LEGALIZACION DE TC DESTINOS 4302840001596798 MES DE NOVIEMBRE 2025 | K532: BANCO DE BOGOTA | O532: =+MONTH(H532) -> 12 | P532: =+YEAR(H532) -> 2025 | Q532: =+VLOOKUP(O532,'COMISIONES ENERO-MARZO 2025 (2)'!$X:$Y,2,0) -> Diciembre
C533: 5305 - DEL SECTOR FINANCIERO | D533: 53059501 | E533: IMPUESTO 4 X 1.000 | F533: 20123 | G533: NIB-00008372 | H533: 46022 | I533: GASTOS BANCARIOS BANCO DE BOGOTA SOBREGIRO 484183223 MES DE DICIEMBRE 2025 | J533: GASTOS BANCARIOS BANCO DE BOGOTA SOBREGIRO 484183223 MES DE DICIEMBRE 2025 | K533: BANCO DE BOGOTA | O533: =+MONTH(H533) -> 12 | P533: =+YEAR(H533) -> 2025 | Q533: =+VLOOKUP(O533,'COMISIONES ENERO-MARZO 2025 (2)'!$X:$Y,2,0) -> Diciembre
C534: 5305 - DEL SECTOR FINANCIERO | D534: 53059501 | E534: IMPUESTO 4 X 1.000 | F534: 11913.6 | G534: NIP-00018159 | H534: 46022 | I534: contabilizacion iva comison 4*1000 | J534: contabilizacion iva comison 4*1000 | K534: BANCOLOMBIA | O534: =+MONTH(H534) -> 12 | P534: =+YEAR(H534) -> 2025 | Q534: =+VLOOKUP(O534,'COMISIONES ENERO-MARZO 2025 (2)'!$X:$Y,2,0) -> Diciembre
C535: 5305 - DEL SECTOR FINANCIERO | D535: 53059501 | E535: IMPUESTO 4 X 1.000 | F535: 11216.8 | G535: NIP-00018075 | H535: 46002 | I535: CONTABILIZAICON IVA COMISON 4*1000 | J535: CONTABILIZAICON IVA COMISON 4*1000 | K535: BANCOLOMBIA | O535: =+MONTH(H535) -> 12 | P535: =+YEAR(H535) -> 2025 | Q535: =+VLOOKUP(O535,'COMISIONES ENERO-MARZO 2025 (2)'!$X:$Y,2,0) -> Diciembre
C536: 5305 - DEL SECTOR FINANCIERO | D536: 53059501 | E536: IMPUESTO 4 X 1.000 | F536: 10288 | G536: NIB-00008371 | H536: 46022 | I536: GASTOS BANCARIOS BANCO BOGOTA CALI CTE 256096355 MES DE DICIEMBRE 2025 | J536: GASTOS BANCARIOS BANCO BOGOTA CALI CTE 256096355 MES DE DICIEMBRE 2025 | K536: BANCO DE BOGOTA | O536: =+MONTH(H536) -> 12 | P536: =+YEAR(H536) -> 2025 | Q536: =+VLOOKUP(O536,'COMISIONES ENERO-MARZO 2025 (2)'!$X:$Y,2,0) -> Diciembre
C537: 5305 - DEL SECTOR FINANCIERO | D537: 53059501 | E537: IMPUESTO 4 X 1.000 | F537: 7382 | G537: NIC-00039498 | H537: 46020 | I537: GG-FEV-32730-LEGALIZACIÓN TARJETA DE CRÉDITO DIRECCIÓN FINANCIERA # 5592 2520 9372 1520 OCTUBRE NOVIEMBRE | J537: GG-FEV-32730-LEGALIZACIÓN TARJETA DE CRÉDITO DIRECCIÓN FINANCIERA # 5592 2520 9372 1520 OCTUBRE NOVIEMBRE | K537: BANCO DAVIVIENDA S.A | O537: =+MONTH(H537) -> 12 | P537: =+YEAR(H537) -> 2025 | Q537: =+VLOOKUP(O537,'COMISIONES ENERO-MARZO 2025 (2)'!$X:$Y,2,0) -> Diciembre
C538: 5305 - DEL SECTOR FINANCIERO | D538: 53059501 | E538: IMPUESTO 4 X 1.000 | F538: 6416.8 | G538: NIP-00018142 | H538: 46014 | I538: CONTABILIZACION IVA COMISON 4*1000 | J538: CONTABILIZACION IVA COMISON 4*1000 | K538: BANCOLOMBIA | O538: =+MONTH(H538) -> 12 | P538: =+YEAR(H538) -> 2025 | Q538: =+VLOOKUP(O538,'COMISIONES ENERO-MARZO 2025 (2)'!$X:$Y,2,0) -> Diciembre
C539: 5305 - DEL SECTOR FINANCIERO | D539: 53059501 | E539: IMPUESTO 4 X 1.000 | F539: 5656.8 | G539: NIP-00018033 | H539: 45993 | I539: CONTABILIZACION IVA COMISON 4*1000 | J539: CONTABILIZACION IVA COMISON 4*1000 | K539: BANCOLOMBIA | O539: =+MONTH(H539) -> 12 | P539: =+YEAR(H539) -> 2025 | Q539: =+VLOOKUP(O539,'COMISIONES ENERO-MARZO 2025 (2)'!$X:$Y,2,0) -> Diciembre
C540: 5305 - DEL SECTOR FINANCIERO | D540: 53059501 | E540: IMPUESTO 4 X 1.000 | F540: 5259.8 | G540: NIB-00008410 | H540: 46022 | I540: TRASLADO DE FONDOS PARA PAGO DE FACTURA AFE846 ASOCACION DE FUNDACIONES FAMILIARES Y EMPRESARIALES - FUNDACION CARMELITA | J540: TRASLADO DE FONDOS PARA PAGO DE FACTURA AFE846 ASOCACION DE FUNDACIONES FAMILIARES Y EMPRESARIALES - FUNDACION CARMELITA | K540: BANCOLOMBIA | O540: =+MONTH(H540) -> 12 | P540: =+YEAR(H540) -> 2025 | Q540: =+VLOOKUP(O540,'COMISIONES ENERO-MARZO 2025 (2)'!$X:$Y,2,0) -> Diciembre
C541: 5305 - DEL SECTOR FINANCIERO | D541: 53059501 | E541: IMPUESTO 4 X 1.000 | F541: 4896.8 | G541: NIP-00018037 | H541: 45994 | I541: contabilizacion iva comison 4*1000 | J541: contabilizacion iva comison 4*1000 | K541: BANCOLOMBIA | O541: =+MONTH(H541) -> 12 | P541: =+YEAR(H541) -> 2025 | Q541: =+VLOOKUP(O541,'COMISIONES ENERO-MARZO 2025 (2)'!$X:$Y,2,0) -> Diciembre
... C566: 5305 - DEL SECTOR FINANCIERO | D566: 53059501 | E566: IMPUESTO 4 X 1.000 | F566: 2659 | G566: NIP-00018050 | H566: 45991 | I566: LEGALIZACIÓN TARJETA DE CREDITO DIRECCIÓN FINANCIERA SEPTIEMBRE OCTUBRE # 5592 2520 9372 1520 | J566: LEGALIZACIÓN TARJETA DE CREDITO DIRECCIÓN FINANCIERA SEPTIEMBRE OCTUBRE # 5592 2520 9372 1520 | K566: BANCO DAVIVIENDA S.A | O566: =+MONTH(H566) -> 11 | P566: =+YEAR(H566) -> 2025 | Q566: =+VLOOKUP(O566,'COMISIONES ENERO-MARZO 2025 (2)'!$X:$Y,2,0) -> Noviembre
F568: =+F570-F569 -> 29231.13
F569: 1.2677561e+08
F570: 1.2680484e+08

Sheet datos
